2022-02-23:20:45:55,896 INFO     [utils.py:157] NumExpr defaulting to 8 threads.
2022-02-23:20:45:56,164 INFO     [execute.py:19] Begin execution
2022-02-23:20:45:56,164 INFO     [execute.py:23] Arguments:
Namespace(app_name='Zeiss_task', best_hyper_params_filepath='/src/data/best_hyper_params', columns_to_drop=['policy_number', 'policy_bind_date', 'policy_state', 'insured_zip', 'incident_location', 'incident_date', 'auto_make', 'auto_model', 'insured_occupation', 'age', 'total_claim_amount'], columns_to_encode=['policy_csl', 'insured_sex', 'insured_education_level', 'insured_hobbies', 'insured_relationship', 'incident_type', 'incident_severity', 'authorities_contacted', 'incident_state', 'incident_city', 'collision_type'], data_filename='./data/insurance_claims.csv', hyper_params={'criterion': 'gini', 'max_depth': 5, 'min_samples_leaf': 2, 'min_samples_split': 2}, model_path='/src/model', preprocess_hobbies=True, schema_filename='/src/data/feature_store/schema.pkl', target='fraud_reported', tune_hyper_params=False)
2022-02-23:20:45:56,168 INFO     [execute.py:25] Starting spark session
2022-02-23:20:46:39,646 INFO     [java_gateway.py:1162] Error while receiving.
Traceback (most recent call last):
  File "C:\Users\anilm\anaconda3\envs\zeiss\lib\site-packages\py4j\java_gateway.py", line 1152, in send_command
    answer = smart_decode(self.stream.readline()[:-1])
  File "C:\Users\anilm\anaconda3\envs\zeiss\lib\socket.py", line 589, in readinto
    return self._sock.recv_into(b)
ConnectionResetError: [WinError 10054] An existing connection was forcibly closed by the remote host
2022-02-23:20:46:39,653 ERROR    [java_gateway.py:1003] Exception while sending command.
Traceback (most recent call last):
  File "C:\Users\anilm\anaconda3\envs\zeiss\lib\site-packages\py4j\java_gateway.py", line 1152, in send_command
    answer = smart_decode(self.stream.readline()[:-1])
  File "C:\Users\anilm\anaconda3\envs\zeiss\lib\socket.py", line 589, in readinto
    return self._sock.recv_into(b)
ConnectionResetError: [WinError 10054] An existing connection was forcibly closed by the remote host

During handling of the above exception, another exception occurred:

Traceback (most recent call last):
  File "C:\Users\anilm\anaconda3\envs\zeiss\lib\site-packages\py4j\java_gateway.py", line 985, in send_command
    response = connection.send_command(command)
  File "C:\Users\anilm\anaconda3\envs\zeiss\lib\site-packages\py4j\java_gateway.py", line 1164, in send_command
    "Error while receiving", e, proto.ERROR_ON_RECEIVE)
py4j.protocol.Py4JNetworkError: Error while receiving
2022-02-23:20:46:41,703 ERROR    [java_gateway.py:1078] An error occurred while trying to connect to the Java server (127.0.0.1:63150)
Traceback (most recent call last):
  File "C:\Users\anilm\anaconda3\envs\zeiss\lib\site-packages\py4j\java_gateway.py", line 929, in _get_connection
    connection = self.deque.pop()
IndexError: pop from an empty deque

During handling of the above exception, another exception occurred:

Traceback (most recent call last):
  File "C:\Users\anilm\anaconda3\envs\zeiss\lib\site-packages\py4j\java_gateway.py", line 1067, in start
    self.socket.connect((self.address, self.port))
ConnectionRefusedError: [WinError 10061] No connection could be made because the target machine actively refused it
2022-02-23:20:46:43,743 ERROR    [java_gateway.py:1078] An error occurred while trying to connect to the Java server (127.0.0.1:63150)
Traceback (most recent call last):
  File "C:\Users\anilm\anaconda3\envs\zeiss\lib\site-packages\py4j\java_gateway.py", line 929, in _get_connection
    connection = self.deque.pop()
IndexError: pop from an empty deque

During handling of the above exception, another exception occurred:

Traceback (most recent call last):
  File "C:\Users\anilm\anaconda3\envs\zeiss\lib\site-packages\py4j\java_gateway.py", line 1067, in start
    self.socket.connect((self.address, self.port))
ConnectionRefusedError: [WinError 10061] No connection could be made because the target machine actively refused it
2022-02-23:20:46:45,760 ERROR    [java_gateway.py:1078] An error occurred while trying to connect to the Java server (127.0.0.1:63150)
Traceback (most recent call last):
  File "C:\Users\anilm\anaconda3\envs\zeiss\lib\site-packages\py4j\java_gateway.py", line 929, in _get_connection
    connection = self.deque.pop()
IndexError: pop from an empty deque

During handling of the above exception, another exception occurred:

Traceback (most recent call last):
  File "C:\Users\anilm\anaconda3\envs\zeiss\lib\site-packages\py4j\java_gateway.py", line 1067, in start
    self.socket.connect((self.address, self.port))
ConnectionRefusedError: [WinError 10061] No connection could be made because the target machine actively refused it
2022-02-23:20:46:47,808 ERROR    [java_gateway.py:1078] An error occurred while trying to connect to the Java server (127.0.0.1:63150)
Traceback (most recent call last):
  File "C:\Users\anilm\anaconda3\envs\zeiss\lib\site-packages\py4j\java_gateway.py", line 929, in _get_connection
    connection = self.deque.pop()
IndexError: pop from an empty deque

During handling of the above exception, another exception occurred:

Traceback (most recent call last):
  File "C:\Users\anilm\anaconda3\envs\zeiss\lib\site-packages\py4j\java_gateway.py", line 1067, in start
    self.socket.connect((self.address, self.port))
ConnectionRefusedError: [WinError 10061] No connection could be made because the target machine actively refused it
2022-02-23:20:46:49,863 ERROR    [java_gateway.py:1078] An error occurred while trying to connect to the Java server (127.0.0.1:63150)
Traceback (most recent call last):
  File "C:\Users\anilm\anaconda3\envs\zeiss\lib\site-packages\py4j\java_gateway.py", line 929, in _get_connection
    connection = self.deque.pop()
IndexError: pop from an empty deque

During handling of the above exception, another exception occurred:

Traceback (most recent call last):
  File "C:\Users\anilm\anaconda3\envs\zeiss\lib\site-packages\py4j\java_gateway.py", line 1067, in start
    self.socket.connect((self.address, self.port))
ConnectionRefusedError: [WinError 10061] No connection could be made because the target machine actively refused it
2022-02-23:20:46:51,905 ERROR    [java_gateway.py:1078] An error occurred while trying to connect to the Java server (127.0.0.1:63150)
Traceback (most recent call last):
  File "C:\Users\anilm\anaconda3\envs\zeiss\lib\site-packages\py4j\java_gateway.py", line 929, in _get_connection
    connection = self.deque.pop()
IndexError: pop from an empty deque

During handling of the above exception, another exception occurred:

Traceback (most recent call last):
  File "C:\Users\anilm\anaconda3\envs\zeiss\lib\site-packages\py4j\java_gateway.py", line 1067, in start
    self.socket.connect((self.address, self.port))
ConnectionRefusedError: [WinError 10061] No connection could be made because the target machine actively refused it
2022-02-23:20:46:53,934 ERROR    [java_gateway.py:1078] An error occurred while trying to connect to the Java server (127.0.0.1:63150)
Traceback (most recent call last):
  File "C:\Users\anilm\anaconda3\envs\zeiss\lib\site-packages\py4j\java_gateway.py", line 929, in _get_connection
    connection = self.deque.pop()
IndexError: pop from an empty deque

During handling of the above exception, another exception occurred:

Traceback (most recent call last):
  File "C:\Users\anilm\anaconda3\envs\zeiss\lib\site-packages\py4j\java_gateway.py", line 1067, in start
    self.socket.connect((self.address, self.port))
ConnectionRefusedError: [WinError 10061] No connection could be made because the target machine actively refused it
2022-02-23:20:46:55,990 ERROR    [java_gateway.py:1078] An error occurred while trying to connect to the Java server (127.0.0.1:63150)
Traceback (most recent call last):
  File "C:\Users\anilm\anaconda3\envs\zeiss\lib\site-packages\py4j\java_gateway.py", line 929, in _get_connection
    connection = self.deque.pop()
IndexError: pop from an empty deque

During handling of the above exception, another exception occurred:

Traceback (most recent call last):
  File "C:\Users\anilm\anaconda3\envs\zeiss\lib\site-packages\py4j\java_gateway.py", line 1067, in start
    self.socket.connect((self.address, self.port))
ConnectionRefusedError: [WinError 10061] No connection could be made because the target machine actively refused it
2022-02-23:20:46:58,43 ERROR    [java_gateway.py:1078] An error occurred while trying to connect to the Java server (127.0.0.1:63150)
Traceback (most recent call last):
  File "C:\Users\anilm\anaconda3\envs\zeiss\lib\site-packages\py4j\java_gateway.py", line 929, in _get_connection
    connection = self.deque.pop()
IndexError: pop from an empty deque

During handling of the above exception, another exception occurred:

Traceback (most recent call last):
  File "C:\Users\anilm\anaconda3\envs\zeiss\lib\site-packages\py4j\java_gateway.py", line 1067, in start
    self.socket.connect((self.address, self.port))
ConnectionRefusedError: [WinError 10061] No connection could be made because the target machine actively refused it
2022-02-23:20:47:00,74 ERROR    [java_gateway.py:1078] An error occurred while trying to connect to the Java server (127.0.0.1:63150)
Traceback (most recent call last):
  File "C:\Users\anilm\anaconda3\envs\zeiss\lib\site-packages\py4j\java_gateway.py", line 929, in _get_connection
    connection = self.deque.pop()
IndexError: pop from an empty deque

During handling of the above exception, another exception occurred:

Traceback (most recent call last):
  File "C:\Users\anilm\anaconda3\envs\zeiss\lib\site-packages\py4j\java_gateway.py", line 1067, in start
    self.socket.connect((self.address, self.port))
ConnectionRefusedError: [WinError 10061] No connection could be made because the target machine actively refused it
2022-02-23:20:47:02,109 ERROR    [java_gateway.py:1078] An error occurred while trying to connect to the Java server (127.0.0.1:63150)
Traceback (most recent call last):
  File "C:\Users\anilm\anaconda3\envs\zeiss\lib\site-packages\py4j\java_gateway.py", line 929, in _get_connection
    connection = self.deque.pop()
IndexError: pop from an empty deque

During handling of the above exception, another exception occurred:

Traceback (most recent call last):
  File "C:\Users\anilm\anaconda3\envs\zeiss\lib\site-packages\py4j\java_gateway.py", line 1067, in start
    self.socket.connect((self.address, self.port))
ConnectionRefusedError: [WinError 10061] No connection could be made because the target machine actively refused it
2022-02-23:20:47:04,134 ERROR    [java_gateway.py:1078] An error occurred while trying to connect to the Java server (127.0.0.1:63150)
Traceback (most recent call last):
  File "C:\Users\anilm\anaconda3\envs\zeiss\lib\site-packages\py4j\java_gateway.py", line 929, in _get_connection
    connection = self.deque.pop()
IndexError: pop from an empty deque

During handling of the above exception, another exception occurred:

Traceback (most recent call last):
  File "C:\Users\anilm\anaconda3\envs\zeiss\lib\site-packages\py4j\java_gateway.py", line 1067, in start
    self.socket.connect((self.address, self.port))
ConnectionRefusedError: [WinError 10061] No connection could be made because the target machine actively refused it
2022-02-23:20:47:06,188 ERROR    [java_gateway.py:1078] An error occurred while trying to connect to the Java server (127.0.0.1:63150)
Traceback (most recent call last):
  File "C:\Users\anilm\anaconda3\envs\zeiss\lib\site-packages\py4j\java_gateway.py", line 929, in _get_connection
    connection = self.deque.pop()
IndexError: pop from an empty deque

During handling of the above exception, another exception occurred:

Traceback (most recent call last):
  File "C:\Users\anilm\anaconda3\envs\zeiss\lib\site-packages\py4j\java_gateway.py", line 1067, in start
    self.socket.connect((self.address, self.port))
ConnectionRefusedError: [WinError 10061] No connection could be made because the target machine actively refused it
2022-02-23:20:47:08,239 ERROR    [java_gateway.py:1078] An error occurred while trying to connect to the Java server (127.0.0.1:63150)
Traceback (most recent call last):
  File "C:\Users\anilm\anaconda3\envs\zeiss\lib\site-packages\py4j\java_gateway.py", line 929, in _get_connection
    connection = self.deque.pop()
IndexError: pop from an empty deque

During handling of the above exception, another exception occurred:

Traceback (most recent call last):
  File "C:\Users\anilm\anaconda3\envs\zeiss\lib\site-packages\py4j\java_gateway.py", line 1067, in start
    self.socket.connect((self.address, self.port))
ConnectionRefusedError: [WinError 10061] No connection could be made because the target machine actively refused it
2022-02-23:20:47:10,270 ERROR    [java_gateway.py:1078] An error occurred while trying to connect to the Java server (127.0.0.1:63150)
Traceback (most recent call last):
  File "C:\Users\anilm\anaconda3\envs\zeiss\lib\site-packages\py4j\java_gateway.py", line 929, in _get_connection
    connection = self.deque.pop()
IndexError: pop from an empty deque

During handling of the above exception, another exception occurred:

Traceback (most recent call last):
  File "C:\Users\anilm\anaconda3\envs\zeiss\lib\site-packages\py4j\java_gateway.py", line 1067, in start
    self.socket.connect((self.address, self.port))
ConnectionRefusedError: [WinError 10061] No connection could be made because the target machine actively refused it
2022-02-23:20:47:12,323 ERROR    [java_gateway.py:1078] An error occurred while trying to connect to the Java server (127.0.0.1:63150)
Traceback (most recent call last):
  File "C:\Users\anilm\anaconda3\envs\zeiss\lib\site-packages\py4j\java_gateway.py", line 929, in _get_connection
    connection = self.deque.pop()
IndexError: pop from an empty deque

During handling of the above exception, another exception occurred:

Traceback (most recent call last):
  File "C:\Users\anilm\anaconda3\envs\zeiss\lib\site-packages\py4j\java_gateway.py", line 1067, in start
    self.socket.connect((self.address, self.port))
ConnectionRefusedError: [WinError 10061] No connection could be made because the target machine actively refused it
2022-02-23:20:47:14,377 ERROR    [java_gateway.py:1078] An error occurred while trying to connect to the Java server (127.0.0.1:63150)
Traceback (most recent call last):
  File "C:\Users\anilm\anaconda3\envs\zeiss\lib\site-packages\py4j\java_gateway.py", line 929, in _get_connection
    connection = self.deque.pop()
IndexError: pop from an empty deque

During handling of the above exception, another exception occurred:

Traceback (most recent call last):
  File "C:\Users\anilm\anaconda3\envs\zeiss\lib\site-packages\py4j\java_gateway.py", line 1067, in start
    self.socket.connect((self.address, self.port))
ConnectionRefusedError: [WinError 10061] No connection could be made because the target machine actively refused it
2022-02-23:20:47:16,418 ERROR    [java_gateway.py:1078] An error occurred while trying to connect to the Java server (127.0.0.1:63150)
Traceback (most recent call last):
  File "C:\Users\anilm\anaconda3\envs\zeiss\lib\site-packages\py4j\java_gateway.py", line 929, in _get_connection
    connection = self.deque.pop()
IndexError: pop from an empty deque

During handling of the above exception, another exception occurred:

Traceback (most recent call last):
  File "C:\Users\anilm\anaconda3\envs\zeiss\lib\site-packages\py4j\java_gateway.py", line 1067, in start
    self.socket.connect((self.address, self.port))
ConnectionRefusedError: [WinError 10061] No connection could be made because the target machine actively refused it
2022-02-23:20:47:18,446 ERROR    [java_gateway.py:1078] An error occurred while trying to connect to the Java server (127.0.0.1:63150)
Traceback (most recent call last):
  File "C:\Users\anilm\anaconda3\envs\zeiss\lib\site-packages\py4j\java_gateway.py", line 929, in _get_connection
    connection = self.deque.pop()
IndexError: pop from an empty deque

During handling of the above exception, another exception occurred:

Traceback (most recent call last):
  File "C:\Users\anilm\anaconda3\envs\zeiss\lib\site-packages\py4j\java_gateway.py", line 1067, in start
    self.socket.connect((self.address, self.port))
ConnectionRefusedError: [WinError 10061] No connection could be made because the target machine actively refused it
2022-02-23:20:47:20,460 ERROR    [java_gateway.py:1078] An error occurred while trying to connect to the Java server (127.0.0.1:63150)
Traceback (most recent call last):
  File "C:\Users\anilm\anaconda3\envs\zeiss\lib\site-packages\py4j\java_gateway.py", line 929, in _get_connection
    connection = self.deque.pop()
IndexError: pop from an empty deque

During handling of the above exception, another exception occurred:

Traceback (most recent call last):
  File "C:\Users\anilm\anaconda3\envs\zeiss\lib\site-packages\py4j\java_gateway.py", line 1067, in start
    self.socket.connect((self.address, self.port))
ConnectionRefusedError: [WinError 10061] No connection could be made because the target machine actively refused it
2022-02-23:20:47:22,515 ERROR    [java_gateway.py:1078] An error occurred while trying to connect to the Java server (127.0.0.1:63150)
Traceback (most recent call last):
  File "C:\Users\anilm\anaconda3\envs\zeiss\lib\site-packages\py4j\java_gateway.py", line 929, in _get_connection
    connection = self.deque.pop()
IndexError: pop from an empty deque

During handling of the above exception, another exception occurred:

Traceback (most recent call last):
  File "C:\Users\anilm\anaconda3\envs\zeiss\lib\site-packages\py4j\java_gateway.py", line 1067, in start
    self.socket.connect((self.address, self.port))
ConnectionRefusedError: [WinError 10061] No connection could be made because the target machine actively refused it
2022-02-23:20:47:24,555 ERROR    [java_gateway.py:1078] An error occurred while trying to connect to the Java server (127.0.0.1:63150)
Traceback (most recent call last):
  File "C:\Users\anilm\anaconda3\envs\zeiss\lib\site-packages\py4j\java_gateway.py", line 929, in _get_connection
    connection = self.deque.pop()
IndexError: pop from an empty deque

During handling of the above exception, another exception occurred:

Traceback (most recent call last):
  File "C:\Users\anilm\anaconda3\envs\zeiss\lib\site-packages\py4j\java_gateway.py", line 1067, in start
    self.socket.connect((self.address, self.port))
ConnectionRefusedError: [WinError 10061] No connection could be made because the target machine actively refused it
2022-02-23:20:47:26,607 ERROR    [java_gateway.py:1078] An error occurred while trying to connect to the Java server (127.0.0.1:63150)
Traceback (most recent call last):
  File "C:\Users\anilm\anaconda3\envs\zeiss\lib\site-packages\py4j\java_gateway.py", line 929, in _get_connection
    connection = self.deque.pop()
IndexError: pop from an empty deque

During handling of the above exception, another exception occurred:

Traceback (most recent call last):
  File "C:\Users\anilm\anaconda3\envs\zeiss\lib\site-packages\py4j\java_gateway.py", line 1067, in start
    self.socket.connect((self.address, self.port))
ConnectionRefusedError: [WinError 10061] No connection could be made because the target machine actively refused it
2022-02-23:20:47:28,636 ERROR    [java_gateway.py:1078] An error occurred while trying to connect to the Java server (127.0.0.1:63150)
Traceback (most recent call last):
  File "C:\Users\anilm\anaconda3\envs\zeiss\lib\site-packages\py4j\java_gateway.py", line 929, in _get_connection
    connection = self.deque.pop()
IndexError: pop from an empty deque

During handling of the above exception, another exception occurred:

Traceback (most recent call last):
  File "C:\Users\anilm\anaconda3\envs\zeiss\lib\site-packages\py4j\java_gateway.py", line 1067, in start
    self.socket.connect((self.address, self.port))
ConnectionRefusedError: [WinError 10061] No connection could be made because the target machine actively refused it
2022-02-23:20:47:30,691 ERROR    [java_gateway.py:1078] An error occurred while trying to connect to the Java server (127.0.0.1:63150)
Traceback (most recent call last):
  File "C:\Users\anilm\anaconda3\envs\zeiss\lib\site-packages\py4j\java_gateway.py", line 929, in _get_connection
    connection = self.deque.pop()
IndexError: pop from an empty deque

During handling of the above exception, another exception occurred:

Traceback (most recent call last):
  File "C:\Users\anilm\anaconda3\envs\zeiss\lib\site-packages\py4j\java_gateway.py", line 1067, in start
    self.socket.connect((self.address, self.port))
ConnectionRefusedError: [WinError 10061] No connection could be made because the target machine actively refused it
2022-02-23:20:47:32,729 ERROR    [java_gateway.py:1078] An error occurred while trying to connect to the Java server (127.0.0.1:63150)
Traceback (most recent call last):
  File "C:\Users\anilm\anaconda3\envs\zeiss\lib\site-packages\py4j\java_gateway.py", line 929, in _get_connection
    connection = self.deque.pop()
IndexError: pop from an empty deque

During handling of the above exception, another exception occurred:

Traceback (most recent call last):
  File "C:\Users\anilm\anaconda3\envs\zeiss\lib\site-packages\py4j\java_gateway.py", line 1067, in start
    self.socket.connect((self.address, self.port))
ConnectionRefusedError: [WinError 10061] No connection could be made because the target machine actively refused it
2022-02-23:20:47:34,753 ERROR    [java_gateway.py:1078] An error occurred while trying to connect to the Java server (127.0.0.1:63150)
Traceback (most recent call last):
  File "C:\Users\anilm\anaconda3\envs\zeiss\lib\site-packages\py4j\java_gateway.py", line 929, in _get_connection
    connection = self.deque.pop()
IndexError: pop from an empty deque

During handling of the above exception, another exception occurred:

Traceback (most recent call last):
  File "C:\Users\anilm\anaconda3\envs\zeiss\lib\site-packages\py4j\java_gateway.py", line 1067, in start
    self.socket.connect((self.address, self.port))
ConnectionRefusedError: [WinError 10061] No connection could be made because the target machine actively refused it
2022-02-23:20:47:36,798 ERROR    [java_gateway.py:1078] An error occurred while trying to connect to the Java server (127.0.0.1:63150)
Traceback (most recent call last):
  File "C:\Users\anilm\anaconda3\envs\zeiss\lib\site-packages\py4j\java_gateway.py", line 929, in _get_connection
    connection = self.deque.pop()
IndexError: pop from an empty deque

During handling of the above exception, another exception occurred:

Traceback (most recent call last):
  File "C:\Users\anilm\anaconda3\envs\zeiss\lib\site-packages\py4j\java_gateway.py", line 1067, in start
    self.socket.connect((self.address, self.port))
ConnectionRefusedError: [WinError 10061] No connection could be made because the target machine actively refused it
2022-02-23:20:47:38,855 ERROR    [java_gateway.py:1078] An error occurred while trying to connect to the Java server (127.0.0.1:63150)
Traceback (most recent call last):
  File "C:\Users\anilm\anaconda3\envs\zeiss\lib\site-packages\py4j\java_gateway.py", line 929, in _get_connection
    connection = self.deque.pop()
IndexError: pop from an empty deque

During handling of the above exception, another exception occurred:

Traceback (most recent call last):
  File "C:\Users\anilm\anaconda3\envs\zeiss\lib\site-packages\py4j\java_gateway.py", line 1067, in start
    self.socket.connect((self.address, self.port))
ConnectionRefusedError: [WinError 10061] No connection could be made because the target machine actively refused it
2022-02-23:20:47:40,897 ERROR    [java_gateway.py:1078] An error occurred while trying to connect to the Java server (127.0.0.1:63150)
Traceback (most recent call last):
  File "C:\Users\anilm\anaconda3\envs\zeiss\lib\site-packages\py4j\java_gateway.py", line 929, in _get_connection
    connection = self.deque.pop()
IndexError: pop from an empty deque

During handling of the above exception, another exception occurred:

Traceback (most recent call last):
  File "C:\Users\anilm\anaconda3\envs\zeiss\lib\site-packages\py4j\java_gateway.py", line 1067, in start
    self.socket.connect((self.address, self.port))
ConnectionRefusedError: [WinError 10061] No connection could be made because the target machine actively refused it
2022-02-23:20:47:42,931 ERROR    [java_gateway.py:1078] An error occurred while trying to connect to the Java server (127.0.0.1:63150)
Traceback (most recent call last):
  File "C:\Users\anilm\anaconda3\envs\zeiss\lib\site-packages\py4j\java_gateway.py", line 929, in _get_connection
    connection = self.deque.pop()
IndexError: pop from an empty deque

During handling of the above exception, another exception occurred:

Traceback (most recent call last):
  File "C:\Users\anilm\anaconda3\envs\zeiss\lib\site-packages\py4j\java_gateway.py", line 1067, in start
    self.socket.connect((self.address, self.port))
ConnectionRefusedError: [WinError 10061] No connection could be made because the target machine actively refused it
2022-02-23:20:47:44,982 ERROR    [java_gateway.py:1078] An error occurred while trying to connect to the Java server (127.0.0.1:63150)
Traceback (most recent call last):
  File "C:\Users\anilm\anaconda3\envs\zeiss\lib\site-packages\py4j\java_gateway.py", line 929, in _get_connection
    connection = self.deque.pop()
IndexError: pop from an empty deque

During handling of the above exception, another exception occurred:

Traceback (most recent call last):
  File "C:\Users\anilm\anaconda3\envs\zeiss\lib\site-packages\py4j\java_gateway.py", line 1067, in start
    self.socket.connect((self.address, self.port))
ConnectionRefusedError: [WinError 10061] No connection could be made because the target machine actively refused it
2022-02-23:20:47:47,12 ERROR    [java_gateway.py:1078] An error occurred while trying to connect to the Java server (127.0.0.1:63150)
Traceback (most recent call last):
  File "C:\Users\anilm\anaconda3\envs\zeiss\lib\site-packages\py4j\java_gateway.py", line 929, in _get_connection
    connection = self.deque.pop()
IndexError: pop from an empty deque

During handling of the above exception, another exception occurred:

Traceback (most recent call last):
  File "C:\Users\anilm\anaconda3\envs\zeiss\lib\site-packages\py4j\java_gateway.py", line 1067, in start
    self.socket.connect((self.address, self.port))
ConnectionRefusedError: [WinError 10061] No connection could be made because the target machine actively refused it
